Workbook

Sheet IT Landscape
A1: IT General Controls Testing - Understanding IT Landscape
B4: SA 315 (Revised) requires auditors to take into account the increasing use and complexity of Information Technology (IT) while assessing the risk of material misstatements during the audits. The extent of the auditor’s understanding of the IT processes, including the extent to which the Entity has general IT controls in place, will vary with the nature and circumstances of the Entity and its IT environment, as well as based on the nature and extent of the controls identified by the auditor. As the Entity’s IT environment and IT systems become more complex, the work performed will likely involve team members with specialized IT skills. _x000D_ The extent of the auditor’s understanding of the IT processes, including the extent to which the entity has general IT controls in place, will vary with the nature and circumstances of the Entity, its IT environment and the nature and extent of the controls identified by the auditor._x000D_ _x000D_ Following aspects of IT are required to be understood for the purposes of understanding the information system: _x000D_ (a) The IT environment relevant to the information system and _x000D_ (b) The Entity’s use of IT (i.e., IT applications relevant to the flows of transactions and processing of information in the information system). _x000D_ _x000D_ The auditor is only required to identify the IT applications and other aspects of the IT environment that are subject to risks arising from the use of IT for the identified controls in the control activities component. These identified controls are focused on information processing controls that directly address the integrity of information (i.e., the completeness, accuracy and validity of transactions and other information). From this, the auditor is then required to identify the related risks arising from the use of IT and the entity’s general IT controls that address such risks. D&I is required for these ‘identified’ IT general controls._x000D_ _x000D_ Information Technology General Controls (ITGCs): IT General Controls are the controls over the entity’s IT processes that support the continued proper operation of the IT environment, including the continued effective functioning of information processing controls and the integrity of information (i.e., the completeness, accuracy and validity of information) in the entity’s information system. _x000D_ _x000D_ IT General Controls are policies and procedures that relate to many applications and support the effective functioning of application controls. They apply to mainframe, miniframe, and end-user environments. IT General controls that maintain the integrity of information and security of data commonly include controls over the following domains: _x000D_ • Data centre and network operations. _x000D_ • Program change. _x000D_ • Access security. _x000D_ • Program Developments_x000D_ _x000D_ The below template can be modified by the auditor to add any additional questions relating to understanding the IT environment or modify the response given for each of the understanding below based on the facts and circumstances applicable to the audit engagement.

Sheet Application Listing
A1: IT General Controls Testing - Application Listing
B3: Name of Client
B4: Audit Period
B7: Application ID | C7: Application Name | D7: Version | E7: Application Description | F7: Underlying Infrastructure | H7: Authentication Mechanism | I7: Interfaces, if any | J7: In-house developed / Off-the-shelf / Procured and highly customized | K7: Source Code Resides (Third Party Vendor/Management) | L7: Hosted on cloud / On Premise | M7: Cloud Vendor details (This field is only applicable when Hosting Detail = "On Cloud") | N7: Is Systems and Organisation Controls (SOC) 1 Type 2 report available for the audit period? (Yes / No) (This field is only applicable when Hosting Detail = "On Cloud") | O7: Data Centre Location | P7: New Deployment/Major Release? | Q7: Go Live Date | R7: Status | S7: Comments
F8: Database (version details)_x000D_ | G8: Operating System (version details)_x000D_

Sheet Key Financial Applications
A1: IT General Controls Testing - Identifying KFA
B3: ='Application Listing'!B3 -> Name of Client | C3: ='Application Listing'!C3
B4: ='Application Listing'!B4 -> Audit Period | C4: ='Application Listing'!C4
B6: Considerations for identifying Key Financial Applications (KFA) - List each applications / tools
B8: Application ID | C8: Application / Tool Name | D8: Application / Tool Description | E8: Mapping to the relevant Business Processes | F8: Impacted Account Balances | G8: Application Scoping considerations | L8: Complex / highly automated business process? | M8: Relevance to the audit | N8: Considered for ITGC scoping? (Yes / No) | O8: Auditor's justification for scoping inclusions and exclusions
G9: Automated Controls including automated elements of semi-automated controls | H9: Automated Calculation and Accounting Procedures | I9: System Generated Reports [Information Used in Controls (IUCs) and Information Produced by Entity (IPEs)] | J9: System Interfaces | K9: Access Security (Sensitive Access and / or Segregation of Duties)

Sheet RAIT
A1: IT General Controls Testing - Risk arising from the use of IT (RAIT)
B3: ='Application Listing'!B3 -> Name of Client | C3: ='Application Listing'!C3
B4: ='Application Listing'!B4 -> Audit Period | C4: ='Application Listing'!C4
B6: Risk arising from the use of IT (RAIT)
G8: RAIT Risk Considerations – Relevancy to Financial Reporting | O8: RAIT Risk Considerations – Technology Platform | W8: RAIT Risk Considerations – Others | Y8: IT Risk Assessment
B9: Application ID | C9: Application Name | D9: Application Description | E9: Applicable Module catering to multiple business processes | F9: Scoping Decision? (Yes / No) | G9: Pervasiveness to the business and financial reporting | H9: Volume of transactions | I9: Automated Controls | J9: Automated Report Logic | K9: System Interfaces | L9: Access Security (Sensitive Access and Segregation of Duties) | M9: Complexity of the business processes / Highly automated processes? (Yes / No) | N9: History of errors relating to IT affecting financial reporting | O9: Status of IT Environment and Governance | P9: No. of Users in the application | Q9: Complexity of security | R9: Number and nature of modifications to the application | S9: Data migration(if applicable) | T9: Usage of systematic jobs | U9: Web-facing application?(Yes / No) | V9: Audit Trail is enabled?(Yes / No) | W9: In-house developed / Off-the-shelf / Procured and highly customized | X9: Source Code resides with the management / Third Party Vendor? | Y9: RAIT Classification_x000D_ (Higher / Not Higher) | Z9: Factors Considered When Assessing Risk Associated with the System

Sheet Understanding Domains
A1: IT General Controls Testing - IT Domains
B3: ='Application Listing'!B3 -> Name of Client | C3: ='Application Listing'!C3
B4: ='Application Listing'!B4 -> Audit Period | C4: ='Application Listing'!C4
B7: In this step, identify the IT domains and system layers that are relevant for each application being audited.
B8: Domains Available - Access Security, Program Change, Program Development, Data Center & Network Operation, Physical Security (where applicable)
B9: Layers Available - Application, Database, Operating System, Network, Physical Security
B10: How to Select Relevant Elements
B11: The auditor must evaluate:
B12: Whether the application is relevant to financial reporting.
B13: Whether automated controls or automated calculations exist.
B14: Whether system-generated reports are relied upon.
B15: Whether interfaces exist.
B16: Whether system configurations impact financial data.
B17: If the application is relevant to financial reporting, the following typically apply:
B18: Access Security → almost always relevant.
... B25: Application
B27: Layer | C27: Domain | D27: Select
B28: Application | C28: Access Security | D28: FALSE
B29: Application | C29: Program Change | D29: FALSE
B30: Application | C30: Program Development | D30: FALSE
B31: Application | C31: Data Center & Network Operation | D31: FALSE
B32: Database | C32: Access Security | D32: FALSE
B33: Database | C33: Program Change | D33: FALSE
B34: Database | C34: Data Center & Network Operation | D34: FALSE
B35: Operating System | C35: Access Security | D35: FALSE
B36: Operating System | C36: Program Change | D36: FALSE
B37: Network | C37: Access Security | D37: FALSE
B38: Network | C38: Program Change | D38: FALSE
B39: Physical Security | C39: Access Security | D39: FALSE

Sheet Understanding Process
A1: IT General Controls Testing - Understanding Process
B3: ='Application Listing'!B3 -> Name of Client | C3: ='Application Listing'!C3
B4: ='Application Listing'!B4 -> Audit Period | C4: ='Application Listing'!C4
B7: In this step:
B8: Review each predefined process carefully.
B9: Select only those processes that are actually operating within the entity’s environment.
B10: Exclude processes that are not applicable (e.g., no in-house development, no privileged access, no job scheduling, etc.).
B11: Add additional processes if the entity performs activities not covered in the predefined list.
B12: The focus at this stage is factual: “Does this process exist in this environment?”.
B13: Do not assess risk yet. First confirm operational reality.
B14: The completeness of process selection directly impacts the completeness of risk identification.
B17: Layer | C17: Domain | D17: Process Code | E17: Process | F17: Select | G17: Guiding Questions
B18: Application | C18: Access Security | D18: ITGC-AS-UPC-T01 | E18: User Access Provisioning and Modification | F18: FALSE | G18: ITGC-AS-UAPM-Q01 (a) What is the entity policy /process for granting new or modified access to the users? (b) What kind of tool, if any, entity uses to facilitate grant new access or modification of existing access to the users? (c) How is access request reviewed and approved by the management? (d) Who is appropriate level of management to approve such requests? (e) How is management evaluates the appropriateness of the access request in line with job responsibilities? (f) How is management ensuring there is no segregation of duties conflicts whilst granting the requested access to the users? (g) Is the segregation of duties are maintained between 'Requester'; 'Approver' and Access granter? (h) How is management ensuring that access grated is in line with the requested and approved access? (i) Is the process followed for new access provisioning is same as for modification of existing access rights? (j) Is the process followed same for Contractors and third party vendors? (k) Is the process different for granting privilege access rights to the user? If yes, what is the change? (l) Any other matter, which is of relevance and would be required to be considered in the risk assessment
B19: Application | C19: Access Security | D19: ITGC-AS-UPC-T02 | E19: Access Revocation | F19: FALSE | G19: ITGC-AS-AR-Q01 (a) What is the entity policy /process for revoking the access rights of the terminated users or users who no longer requires access for business reason (b) What is the process for identification of users for termination of access rights and what are the timelines for such identification? (c) What kind of tool, if any, entity uses for communicating revocation of the access rights? (d) What is the frequency at which access rights are revoked post communication of terminated users? (e) What is the management policy in terms of time required for access revocation? (f) Is the user account is disabled with no access rights or deleted from the system post termination of users? (g) Is the process of access revocation automated or manual? If automated, how's the workflow configured? (h) How management monitors if access rights are removed; users ids are disabled / deleted post termination as per the defined policies / protocols? If yes, what is the frequency of such monitoring? (j) What and how information is generated to monitor the timely deactivation of users rights for the terminated users and / or users not requiring access during the business reasons? (k) How management evaluates the competency of the users performing the control? (l) Is the process followed same for contractors and third party vendors? (m) Any other matter, which is of relevance and would be required to be considered in the risk assessment
B20: Application | C20: Access Security | D20: ITGC-AS-UPC-T03 | E20: User Access Reviews (UAR) | F20: FALSE | G20: ITGC-AS-UAR-Q01 (a) What is the entity policy /process for reviewing the access rights of the users on the periodic basis? (b) Is management actually carrying out the User Access Rights reviews to ensure access rights granted s in line with the job responsibilities? (c) What is the frequency of the UARs? (d) Who has been entrusted with the review responsibilities? Do they have competency to review what is intended by the management? (e) Is the person carrying out the review is independent of the person having privileged level access in the system? Is segregation of duties maintained? (f) How the population of Users identified and classified for the reviews? Is the standard report and customized? (g) How is management comfortable with the accuracy and completeness of the reports (Standard or Customised)? (h) Is the reports contains accurate information about the users and the roles / permissions assigned to them? (i) Is the review performed and documented at a level of detail that is sufficient to determine whether access rights are consistent with the User's current job responsibilities? (j) If the reviewer has access to the system, is his access independently reviewed to avoid self review threat? (k) How is the management dealing with the exceptions noted during the review? How is that been communicated to the remediation / rectification? (l) What is the timeline defined to complete the access reviews, including remediation / rectification of the identified exceptions? (m) Is management using any tool to facilitate UARs? If yes, how is the workflow configured? (n) What evidence is retained to demonstrate the UARs are performed? (o) Any other matter, which is of relevance and would be required to be considered in the risk assessment
B21: Application | C21: Access Security | D21: ITGC-AS-UPC-T04 | E21: Privilege Access Management | F21: FALSE | G21: ITGC-AS-PAM-Q01 (a) What is the entity policy/process for managing users with privilege access rights? (b) Do any business users, including finance users have administrator rights in the system? If yes, explain the rational for providing administrator level access to these users? (c) Is application privilege access assigned to the authorised IT personnel? (d) Are database administrators are the only users with privilege level access to the database / data files? (e) What profiles / roles grants users the privilege access rights? (f) If system have generic user accounts / service accounts, is access adequately restricted to authorised individuals? (g) Is the login credentials restricted only to authorised individuals? (h) Is password vault or similar tool used to restrict access to generic accounts / service accounts? (i) Does management have a process to monitor the activities performed by the privilege access users periodically? (j) Who is authorised to perform activity log review of the privilege users? (k) Does the reviewer has access to the privileged accounts in the system? If yes, how is reviewers activity log been monitored? (l) How is the information generated in relating to the activity log, and how it is being monitored for completeness and accuracy? (m) Is there any timelines defined to complete the activity log reviews by the management? (n) How exceptions are handled while performing the review? Does entity have a defined process around it? (o) Is there an evidence maintained and retained demonstrating review performed by the reviewer? (p) Any other matter, which is of relevance and would be required to be considered in the risk assessment
B22: Application | C22: Access Security | D22: ITGC-AS-UPC-T05 | E22: Password Management / System Authentication | F22: FALSE | G22: ITGC-AS-PM-Q01 (a) What is the entity policy /process for managing authentication / password within the organization? (b) Does system user authenticate through unique user id and password? (c) Is the system configured to authenticate through single sign-on functionality or similar mechanism? (d) Is system configured to have Multi-factor Authentication (MFA)? (e) If authenticated through passwords, how the password parameters are configured? Is it aligned to the industry best practices (NIST)? (For e.g. Password complexity; password length; password expiration limit; Lock out period) (f) Are password parameters enforced to all the accounts including generic / system / service accounts? (g) How management deals with exceptions to the policies? (h) Any other matter, which is of relevance and would be required to be considered in the risk assessment
B23: Application | C23: Access Security | D23: ITGC-AS-RDG-T01 | E23: Role Design and SOD Governance | F23: FALSE | G23: ITGC-AS-RDG-Q01 (a) Is there a documented role design framework? (b) Are roles mapped to business functions and job responsibilities? (c) Is a Segregation of Duties (SOD) matrix maintained? (d) Are roles periodically reviewed for appropriateness? (e) How are SOD conflicts identified and mitigated? (f) Is management approval obtained for role creation or modification?
B24: Application | C24: Program Change | D24: ITGC-PC-UPC-T01 | E24: Changes to Application Programs and Configurations | F24: FALSE | G24: ITGC-PC-CAPC-Q01 (a) What is the entity policy /process for managing changes for Applications; Databases / Datafiles; Operating System or Network layers? (b) Does the entity have ability to modify the source code in the system? (c) How entity develops any changes to the application programs or configurations and / or underlying infrastructure, including system audit trail? (d) What is the frequency for making changes to the system? (e) How does the system track that all the change are migrated to production environment? (f) What kind of tools, if any, entity uses to manage migration of changes to the production environment? (g) If tool is used to implement changes to the production environment, how is the administrative / privilege access to the tool managed? Is access restricted to the authorised individuals (h) Is the development activities outsourced to third party service provider? (i) If development activities are outsourced, how are Vendor's access to the systems managed? (j) What is the architecture of the application landscape? Does entity have separate instance for Development; Quality and Production environment? (k) How entity manages access to all three environment? Is Segregation of duties maintained between all the environments? (l) How is segregation of duties maintained in relation to access with developmental rights and Implementational rights? (m) Is management (Business and / or IT) authorization and / or approval for changes provided and documented prior to the implementation? (n) Is the testing of change performed prior to management approval for implementation into production environment? (o) Is there segregation of duties maintained between User with development rights and approval of changes? (p) Does entity have a process for periodic change monitoring to review changes implemented into production for appropriateness? (q) If yes, what is the periodicity of such monitoring? (r) Is the change monitoring reviewer is independent of users having development and implementation access? (s) Are the reviewers competent to perform such reviews? (t) Any other matter, which is of relevance and would be required to be considered in the risk assessment
B25: Application | C25: Program Change | D25: ITGC-PC-DMG-T01 | E25: Data Migration Governance | F25: FALSE | G25: ITGC-PC-DMG-Q01 (a) What is the entity’s policy governing data migrations? (b) Are data migrations formally approved prior to execution? (c) Are test migrations performed before production migration? (d) Is reconciliation performed between source and target systems? (e) How are migration errors identified and resolved? (f) Is there documentation evidencing management sign-off prior to go-live?
B26: Application | C26: Program Development | D26: ITGC-PD-UPC-T01 | E26: System Development Life Cycle (SDLC) | F26: FALSE | G26: ITGC-PD-SDLC-Q01 (a) What is the entity policy /process for System Development Life Cycle for Applications; Databases / Datafiles; Operating System or Network layers? (b) How's entity identifies the need to development of the new application or supporting infrastructure? (c) What level of management approvals taken to initiate the system developmental process? (d) How is management defines the requirement for 'to be' system? (e) What is the level of Business and Information Technology (IT) involvement in identifying the requirement / features for the 'To be' system? (f) Is the System requirement document / Blue Print is approved by the Management / Those Charged with Governance (TCWG)? (g) Is the Developmental activities outsourced to third party vendor or in-house managed? (h) If outsourced, what criteria management evaluates to shortlist and selection of the vendor? (i) For in-house development, how is Team identified and selected? (j) What is the model of Software Development Life Cycle (SDLC) process? For e.g. Waterfall or Agile model. (k) What is the governance mechanism to monitor the progress of the development process? (l) What level of testing is carried out to ensure system is being developed as per the set requirement? For e.g. Unit Testing; Integration Testing; User Acceptance Testing (UAT). (m) How does the management identify and authorize teams to carry out testing during the developmental phases? (n) How does the management track the issues identified during developmental or testing phases through resolution? (o) Is there any Data Migration involved in the process? If yes, what is the management plan for the migration? (p) What control management has implemented to ensure 'Completeness and Accuracy' of the data to be migrated? (q) How is management identifies data that needs cleansing during the migration process and who approves the this? (r) What kind of evidences are maintained demonstrating controls exercised over migration? (s) Who has provided 'Go Live' approval post implementation? (t) Has management provided training to the end users to ensure smooth operation of the system and transaction processing? (u) How the controls are exercised during the Hypercare period post implementation till the system is stabilised? (v) How is management monitors the Activity Log for users with privilege access rights? (w) Any other matter, which is of relevance and would be required to be considered in the risk assessment
B27: Application | C27: Program Development | D27: ITGC-PD-ENV-T01 | E27: IT Environment Governance | F27: FALSE | G27: ITGC-PD-ENV-Q01 (a) Is a comprehensive inventory of applications and supporting infrastructure maintained? (b) How frequently is the IT inventory reviewed and updated? (c) Are new systems formally added to the inventory upon implementation? (d) Is system ownership clearly defined? (e) Does the inventory support scoping of ITGC controls?
B28: Application | C28: Data Center & Network Operation | D28: ITGC-DCNO-UPC-T03 | E28: Job Monitoring | F28: FALSE | G28: ITGC-DCNO-JM-Q01 (a) What is the entity policy /process for identifying critical jobs relevant for financial reporting? (b) How these critical jobs are monitored for success and failure runs? (c) How is entity ensures access to Jobs are restricted to authorised users only? (d) How entity manages changes to the configurations relating to jobs? (e) Any other matter, which is of relevance and would be required to be considered in the risk assessment
B29: Application | C29: Data Center & Network Operation | D29: ITGC-DCNO-UPC-T04 | E29: Incident Management | F29: FALSE | G29: ITGC-DCNO-IM-Q01 (a) Does the entity have a defined policies /process for identifying; reporting and resolving Incidents? (b) What is the entity process in classifying the incidents? For e.g. High, Medium or Low? (c) Is there any process of robust monitoring in place at-least for High; Medium category of the incidents? (d) Is entity uses any tool to track such incidents and subsequent communication and resolution? (e) Does Cyber breach related incidents also goes through the same incident management flow or there is a separate process? If not, how Cyber related incidents are tracked, reported and resolved? (f) Any other matter, which is of relevance and would be required to be considered in the risk assessment
... B53: Physical Security | C53: Access Security | D53: ITGC-AS-DCG-T01 | E53: Data Center Physical Monitoring | F53: FALSE | G53: ITGC-AS-DCG-Q01 (a) Is physical access to data centers restricted to authorized personnel? (b) Are visitor logs maintained and periodically reviewed? (c) Is CCTV monitoring implemented and footage retained? (d) Are environmental controls (temperature, fire suppression) monitored? (e) Are periodic reviews conducted of access badges and physical access rights?

Sheet Understanding Risks
A1: IT General Controls Testing - Understanding Process
B3: ='Application Listing'!B3 -> Name of Client | C3: ='Application Listing'!C3
B4: ='Application Listing'!B4 -> Audit Period | C4: ='Application Listing'!C4
B7: In this step:
B8: Review each predefined process carefully.
B9: Select only those processes that are actually operating within the entity’s environment.
B10: Exclude processes that are not applicable (e.g., no in-house development, no privileged access, no job scheduling, etc.).
B11: Add additional processes if the entity performs activities not covered in the predefined list.
B12: The focus at this stage is factual: “Does this process exist in this environment?”.
B13: Do not assess risk yet. First confirm operational reality.
B14: The completeness of process selection directly impacts the completeness of risk identification.
B17: Layer | C17: Domain | D17: Process Code | E17: Process | F17: Risk ID | G17: Risk | H17: ROMM Exists | I17: Justification (If ROMM does not exist) | J17: Whether Risk Due to Fraud? * | K17: Assertions | L17: Risk/Assertion Classification | M17: Select
B18: Application | C18: Access Security | D18: ITGC-AS-UPC-T01 | E18: User Access Provisioning and Modification | F18: ITGC-AS-UAPM-R-001 | G18: Users having unauthorised access to the application beyond their job responsibilities | M18: FALSE
B19: Application | C19: Access Security | D19: ITGC-AS-UPC-T02 | E19: Access Revocation | F19: ITGC-AS-AR-R-001 | G19: User access rights are not revoked on a timely basis in the Application, which may lead to un-authorised access to the users. | M19: FALSE
B20: Application | C20: Access Security | D20: ITGC-AS-UPC-T03 | E20: User Access Reviews (UAR) | F20: ITGC-AS-UAR-R-001 | G20: Users having unauthorised access to the application beyond their job responsibilities | M20: FALSE
B21: Application | C21: Access Security | D21: ITGC-AS-UPC-T04 | E21: Privilege Access Management | F21: ITGC-AS-PAM-R-001 | G21: Unauthorised users having access to privilege level accounts in the application. | M21: FALSE
B22: Application | C22: Access Security | D22: ITGC-AS-UPC-T04 | E22: Privilege Access Management | F22: ITGC-AS-PAM-R-005 | G22: Unauthorised activities at the application layer were carried out by the users having privileged access. | M22: FALSE
B23: Application | C23: Access Security | D23: ITGC-AS-UPC-T05 | E23: Password Management / System Authentication | F23: ITGC-AS-PM-R-001 | G23: Password management protocols are not followed due to which applications are not adequately configured or updated to restrict system access to properly authorized and appropriate users | M23: FALSE
B24: Application | C24: Access Security | D24: ITGC-AS-RDG-T01 | E24: Role Design and SOD Governance | F24: ITGC-AS-RDG-R-001 | G24: Inadequate role design may result in segregation of duties conflicts or inappropriate access to critical functions. | M24: FALSE
B25: Application | C25: Program Change | D25: ITGC-PC-UPC-T01 | E25: Changes to Application Programs and Configurations | F25: ITGC-PC-CAPC-R-001 | G25: Inappropriate changes are made to application systems or programs that contain relevant automated controls (i.e., configurable settings, automated algorithms, automated calculations); Interfaces; system audit trail and/or report logic. | M25: FALSE
B26: Application | C26: Program Change | D26: ITGC-PC-DMG-T01 | E26: Data Migration Governance | F26: ITGC-PC-DMG-R-001 | G26: Data migration activities may result in incomplete, inaccurate or unauthorized data transfer impacting financial reporting. | M26: FALSE
B27: Application | C27: Program Development | D27: ITGC-PD-UPC-T01 | E27: System Development Life Cycle (SDLC) | F27: ITGC-PD-SDLC-R-001 | G27: Appropriate development life cycle that is relevant to the current operations of the entity is not followed thereby impacting smooth functioning of application and related programs including automated algorithms, automated calculations, associated configurations, interfaces and report logics. | M27: FALSE
B28: Application | C28: Program Development | D28: ITGC-PD-UPC-T01 | E28: System Development Life Cycle (SDLC) | F28: ITGC-PD-SDLC-R-002 | G28: Data has not been migrated completely and accurately. | M28: FALSE
B29: Application | C29: Program Development | D29: ITGC-PD-UPC-T01 | E29: System Development Life Cycle (SDLC) | F29: ITGC-PD-SDLC-R-003 | G29: Unauthorised users having access to privilege level accounts in the application. | M29: FALSE
... B61: Physical Security | C61: Access Security | D61: ITGC-AS-DCG-T01 | E61: Data Center Physical Monitoring | F61: ITGC-AS-DCG-R-001 | G61: Unauthorized physical access to data centers may compromise system availability, integrity or confidentiality. | M61: FALSE

Sheet Understanding Controls
A1: IT General Controls Testing - Understanding Controls
B3: ='Application Listing'!B3 -> Name of Client | C3: ='Application Listing'!C3
B4: ='Application Listing'!B4 -> Audit Period | C4: ='Application Listing'!C4
B7: This section requires the auditor to identify and document the controls implemented by management to mitigate the risks selected in the previous stage.
B8: This section requires the auditor to identify and document the controls implemented by management to mitigate the risks selected in the previous stage.
B9: For each risk:
B10: Identify the control(s) that directly address the risk.
B11: Document the control activity clearly and precisely.
B12: Capture key attributes including nature of control (Automated / Semi-automated / Manual / Review), related IT system (where applicable), control owner, frequency, and Information Used in Control (IUC) along with its source.
B13: Ensure the control logically mitigates the specific risk identified.
B14: If predefined controls are not sufficient to address the risk, additional controls must be documented.
B15: This stage records the existence and structure of controls. Evaluation of design adequacy and operating effectiveness will be performed in subsequent phases.
B18: Application Name | C18: Layer | D18: Domain | E18: Process Code | F18: Process | G18: Risk ID | H18: Risk | I18: Control ID | J18: Control Activity | K18: Nature of Control | L18: Related IT System (If Nature of Control is Automated/Semi-automated) | M18: Control Owner | N18: Control Frequency | O18: IUC ID | P18: IUC Description | Q18: IUC Source
B19: Application Name | C19: Application | D19: Access Security | E19: ITGC-AS-UPC-T01 | F19: User Access Provisioning and Modification | G19: ITGC-AS-UAPM-R-001 | H19: Users having unauthorised access to the application beyond their job responsibilities | I19: ITGC-AS-UAPM-C-001 | J19: New User Access / modification of existing access rights requests to the application are made by the relevant user and are reviewed and authorized by the Reporting Manager of the user to whom access rights has to be granted after ensuring that access rights corresponds with the job description, roles and responsibilities. The Information Technology (IT) user who grants access rights reviews the approval by the Reporting Manager for completeness and accuracy before granting / modification of access rights. | O19: ITGC-AS-UAPM-IUC-01 | P19: Access Request Form
B20: Application Name | C20: Application | D20: Access Security | E20: ITGC-AS-UPC-T02 | F20: Access Revocation | G20: ITGC-AS-AR-R-001 | H20: User access rights are not revoked on a timely basis in the Application, which may lead to un-authorised access to the users. | I20: ITGC-AS-AR-C-001 | J20: Intimation for revocation of user access rights are received from Human Resources(HR) on / or before the last working day of the user. IT team reviews such intimations and initiates the process for revocation of rights within the timelines for revocation that has been prescribed by the management. The revocation is communicated to HR by the respective IT team within the timelines prescribed by the management. If the HR does not receive such confirmation from the IT team within the timelines prescribed by the management, they follow up with the IT team to ensure the revocation. In case the user has accessed the application after the last working day but before the revocation of his access rights, the Reporting Manager of such user reviews the details of such access by this user to determine the nature and extent of such access and affirms that there is no matter that has to be pursued because of such access. | O20: ITGC-AS-AR-IUC-01 | P20: Leavers report: 1. Employee ID; 2. Employee Name: 3. Employee's Department 4. Last Working Day of the Employee 5. Deactivation Date in the application
B21: Application Name | C21: Application | D21: Access Security | E21: ITGC-AS-UPC-T02 | F21: Access Revocation | G21: ITGC-AS-AR-R-001 | H21: User access rights are not revoked on a timely basis in the Application, which may lead to un-authorised access to the users. | I21: ITGC-AS-AR-C-001 | J21: Intimation for revocation of user access rights are received from Human Resources(HR) on / or before the last working day of the user. IT team reviews such intimations and initiates the process for revocation of rights within the timelines for revocation that has been prescribed by the management. The revocation is communicated to HR by the respective IT team within the timelines prescribed by the management. If the HR does not receive such confirmation from the IT team within the timelines prescribed by the management, they follow up with the IT team to ensure the revocation. In case the user has accessed the application after the last working day but before the revocation of his access rights, the Reporting Manager of such user reviews the details of such access by this user to determine the nature and extent of such access and affirms that there is no matter that has to be pursued because of such access. | O21: ITGC-AS-AR-IUC-02 | P21: Access Log report for the terminated Users
B22: Application Name | C22: Application | D22: Access Security | E22: ITGC-AS-UPC-T03 | F22: User Access Reviews (UAR) | G22: ITGC-AS-UAR-R-001 | H22: Users having unauthorised access to the application beyond their job responsibilities | I22: ITGC-AS-UAR-C-001 | J22: On a periodic basis, user responsible for managing the application extracts the listing of users along with users roles / access right in the IT application and shares it with Business Heads for their review along with a checklist describing the activities that Business Head needs to perform during their reviews and also a description of what access rights are given for each roles and responsibilities. On receipt of the list, Business Head performs the following: 1. Reviews the listing to verify if there is no resigned employee who appears as a user in the list; 2. Reviews the access rights assigned to each of the user in the list to ensure this is appropriate in line with their job responsibilities; 3. If there are any exception that needs to be remediated, Business Head communicates this to the IT team for necessary remediation. 4. Once identified exceptions in the review are remediated and communicated back to the Business Head by the IT team, Business Head reviews the listing again to confirm that necessary remediation has taken place. | O22: ITGC-AS-UAR-IUC-01 | P22: Active User Listing: 1. Employee Name; 2. Employee ID; 3. User ID in the system; 4. Roles / permissions assigned to the user ID 4. Department of the user
B23: Application Name | C23: Application | D23: Access Security | E23: ITGC-AS-UPC-T04 | F23: Privilege Access Management | G23: ITGC-AS-PAM-R-001 | H23: Unauthorised users having access to privilege level accounts in the application. | I23: ITGC-AS-PAM-C-001 | J23: Super Users / Administrative privileges, including sensitive Generic IDs to the applications are monitored on a periodic basis by the authorised IT personnel who is independent and does not have privilege rights to ensure access is in line with the job responsibilities. | O23: ITGC-AS-PAM-IUC-01 | P23: Privilege Users Listing: 1. Employee Name; 2. Employee ID; 3. User ID in the system; 4. Roles / permissions assigned to the user ID
B24: Application Name | C24: Application | D24: Access Security | E24: ITGC-AS-UPC-T04 | F24: Privilege Access Management | G24: ITGC-AS-PAM-R-005 | H24: Unauthorised activities at the application layer were carried out by the users having privileged access. | I24: ITGC-AS-PAM-C-005 | J24: Transactions and/ or activity logs of Super Users / Administrative privilege users accounts to the applications are monitored on a periodic basis by the authorised IT personnel who is independent and does not have privilege rights to ensure no unauthorised activities were carried out. | O24: ITGC-AS-PAM-IUC-05 | P24: Transaction / activity logs for the selected period for the users having privilege accesses.
B25: Application Name | C25: Application | D25: Access Security | E25: ITGC-AS-UPC-T05 | F25: Password Management / System Authentication | G25: ITGC-AS-PM-R-001 | H25: Password management protocols are not followed due to which applications are not adequately configured or updated to restrict system access to properly authorized and appropriate users | I25: ITGC-AS-PM-C-001 | J25: Access to the application is authenticated through unique user IDs and passwords or other methods as a mechanism for validating that users are authorized to gain access to the system. Password parameters meet entity and/or industry standards: - Password minimum length; - Password complexity; - Password expiration; - Account lockout period Further user authentication is also validated through Multi Factor Authentication (MFA).
B26: Application Name | C26: Application | D26: Access Security | E26: ITGC-AS-UPC-T05 | F26: Password Management / System Authentication | G26: ITGC-AS-PM-R-001 | H26: Password management protocols are not followed due to which applications are not adequately configured or updated to restrict system access to properly authorized and appropriate users | I26: ITGC-AS-PM-C-002 | J26: Application enforces changing of the default passwords for standard generic accounts / service accounts.
B27: Application Name | C27: Application | D27: Access Security | E27: ITGC-AS-RDG-T01 | F27: Role Design and SOD Governance | G27: ITGC-AS-RDG-R-001 | H27: Inappropriate role design may allow segregation of duties conflicts. | I27: ITGC-AS-RDG-C-001 | J27: Roles are periodically reviewed against SOD matrix and approved by management. | O27: ITGC-AS-RDG-IUC-01 | P27: Role to Permission Mapping Document
B28: Application Name | C28: Application | D28: Access Security | E28: ITGC-AS-RDG-T01 | F28: Role Design and SOD Governance | G28: ITGC-AS-RDG-R-001 | H28: Inappropriate role design may allow segregation of duties conflicts. | I28: ITGC-AS-RDG-C-001 | J28: Roles are periodically reviewed against SOD matrix and approved by management. | O28: ITGC-AS-RDG-IUC-02 | P28: Segregation of Duties Matrix
B29: Application Name | C29: Application | D29: Program Change | E29: ITGC-PC-UPC-T01 | F29: Changes to Application Programs and Configurations | G29: ITGC-PC-CAPC-R-001 | H29: Inappropriate changes are made to application systems or programs that contain relevant automated controls (i.e., configurable settings, automated algorithms, automated calculations); Interfaces; system audit trail and/or report logic. | I29: ITGC-PC-CAPC-C-001 | J29: Any changes to the application programs or source codes or configurations are adequately tested and approved by the appropriate management to ensure: 1. Requested changes are aligned to the business requirement 2. Changes to be migrated are in line with what is requested by the business / Information Technology (IT) 3. Approval is provided for migration to production environment only after ensuring adequate testing of the changes and verifying business / IT approval for development of changes
B30: Application Name | C30: Application | D30: Program Change | E30: ITGC-PC-UPC-T01 | F30: Changes to Application Programs and Configurations | G30: ITGC-PC-CAPC-R-001 | H30: Inappropriate changes are made to application systems or programs that contain relevant automated controls (i.e., configurable settings, automated algorithms, automated calculations); Interfaces; system audit trail and/or report logic. | I30: ITGC-PC-CAPC-C-002 | J30: Development, testing and production environments are segregated for changes to the applications and / or configurations.
B31: Application Name | C31: Application | D31: Program Change | E31: ITGC-PC-UPC-T01 | F31: Changes to Application Programs and Configurations | G31: ITGC-PC-CAPC-R-001 | H31: Inappropriate changes are made to application systems or programs that contain relevant automated controls (i.e., configurable settings, automated algorithms, automated calculations); Interfaces; system audit trail and/or report logic. | I31: ITGC-PC-CAPC-C-003 | J31: Access to implement changes into the application production environment is appropriately restricted and segregated from the development environment.
B32: Application Name | C32: Application | D32: Program Change | E32: ITGC-PC-UPC-T01 | F32: Changes to Application Programs and Configurations | G32: ITGC-PC-CAPC-R-001 | H32: Inappropriate changes are made to application systems or programs that contain relevant automated controls (i.e., configurable settings, automated algorithms, automated calculations); Interfaces; system audit trail and/or report logic. | I32: ITGC-PC-CAPC-C-004 | J32: On a periodic basis, appropriate management obtains the Change log report from the applications / tool and performs the review of all the changes for its appropriates and validity. Any exception noted during the review is communicated to the Application IT team for responses and remediation. Post remediation as per the instructions from the IT Head, IT team communicates back to the IT Head and thereafter IT Head reviews it further to ensure appropriateness of the remediation performed by the IT Team. | O32: ITGC-PC-CAPC-IUC-01 | P32: Change Log report from the application containing changes migrated to production environment during the given period
B33: Application Name | C33: Application | D33: Program Change | E33: ITGC-PC-DMG-T01 | F33: Data Migration Governance | G33: ITGC-PC-DMG-R-001 | H33: Data migration may result in incomplete or inaccurate data transfer. | I33: ITGC-PC-DMG-C-001 | J33: All data migrations are approved, tested and reconciled prior to go-live. | O33: ITGC-PC-DMG-IUC-01 | P33: Data Migration Plan and Approval Document
B34: Application Name | C34: Application | D34: Program Change | E34: ITGC-PC-DMG-T01 | F34: Data Migration Governance | G34: ITGC-PC-DMG-R-001 | H34: Data migration may result in incomplete or inaccurate data transfer. | I34: ITGC-PC-DMG-C-001 | J34: All data migrations are approved, tested and reconciled prior to go-live. | O34: ITGC-PC-DMG-IUC-02 | P34: Data Reconciliation Report between source and target systems
B35: Application Name | C35: Application | D35: Program Development | E35: ITGC-PD-UPC-T01 | F35: System Development Life Cycle (SDLC) | G35: ITGC-PD-SDLC-R-001 | H35: Appropriate development life cycle that is relevant to the current operations of the entity is not followed thereby impacting smooth functioning of application and related programs including automated algorithms, automated calculations, associated configurations, interfaces and report logics. | I35: ITGC-PD-SDLC-C-001 | J35: Development of new systems / enhancements are adequately approved by appropriate management before being developed taking into consideration the current operations of the entity. | O35: ITGC-PD-SDLC-IUC-01 | P35: Blue print of the new development
B36: Application Name | C36: Application | D36: Program Development | E36: ITGC-PD-UPC-T01 | F36: System Development Life Cycle (SDLC) | G36: ITGC-PD-SDLC-R-001 | H36: Appropriate development life cycle that is relevant to the current operations of the entity is not followed thereby impacting smooth functioning of application and related programs including automated algorithms, automated calculations, associated configurations, interfaces and report logics. | I36: ITGC-PD-SDLC-C-002 | J36: Required level of testing is carried out during the development phase in terms of Unit Testing; System Integration testing; User Acceptance testing before Go Live is approved by the management.
B37: Application Name | C37: Application | D37: Program Development | E37: ITGC-PD-UPC-T01 | F37: System Development Life Cycle (SDLC) | G37: ITGC-PD-SDLC-R-001 | H37: Appropriate development life cycle that is relevant to the current operations of the entity is not followed thereby impacting smooth functioning of application and related programs including automated algorithms, automated calculations, associated configurations, interfaces and report logics. | I37: ITGC-PD-SDLC-C-003 | J37: Issues noted during program developments are monitored by the IT Head / Business Head / Steering Committee and resolved before go live. | O37: ITGC-PD-SDLC-IUC-02 | P37: Tracker of issue log / listing where all issues are logged
B38: Application Name | C38: Application | D38: Program Development | E38: ITGC-PD-UPC-T01 | F38: System Development Life Cycle (SDLC) | G38: ITGC-PD-SDLC-R-002 | H38: Data has not been migrated completely and accurately. | I38: ITGC-PD-SDLC-C-004 | J38: Management with appropriate authority has performed the reconciliation of the data to be migrated with the actual migrated data to ensure completeness and accuracy of the migrated data. Reconciliation are approved and signed off by the management demonstrating the review. | O38: ITGC-PD-SDLC-IUC-03 | P38: Log of data from Old System
B39: Application Name | C39: Application | D39: Program Development | E39: ITGC-PD-UPC-T01 | F39: System Development Life Cycle (SDLC) | G39: ITGC-PD-SDLC-R-002 | H39: Data has not been migrated completely and accurately. | I39: ITGC-PD-SDLC-C-004 | J39: Management with appropriate authority has performed the reconciliation of the data to be migrated with the actual migrated data to ensure completeness and accuracy of the migrated data. Reconciliation are approved and signed off by the management demonstrating the review. | O39: ITGC-PD-SDLC-IUC-04 | P39: Log of data from Newly implemented System
B40: Application Name | C40: Application | D40: Program Development | E40: ITGC-PD-UPC-T01 | F40: System Development Life Cycle (SDLC) | G40: ITGC-PD-SDLC-R-003 | H40: Unauthorised users having access to privilege level accounts in the application. | I40: ITGC-PD-SDLC-C-005 | J40: Management monitors and activity log of the users given privilege access on a periodic basis to ensure no un-authorised activities during the hypercare period. Exceptions noted are dealt with appropriately. | O40: ITGC-PD-SDLC-IUC-05 | P40: Tracker of activity log / listing from tool where all activities are logged
B41: Application Name | C41: Application | D41: Program Development | E41: ITGC-PD-ENV-T01 | F41: IT Environment Governance | G41: ITGC-PD-ENV-R-001 | H41: Lack of system inventory may result in incomplete ITGC coverage. | I41: ITGC-PD-ENV-C-001 | J41: An updated inventory of applications and supporting infrastructure is maintained and reviewed. | O41: ITGC-PD-ENV-IUC-01 | P41: IT System Inventory Listing
B42: Application Name | C42: Application | D42: Data Center & Network Operation | E42: ITGC-DCNO-UPC-T03 | F42: Job Monitoring | G42: ITGC-DCNO-JM-R-001 | H42: Users having unauthorised access to administer Jobs Schedule beyond their job responsibilities | I42: ITGC-DCNO-JM-C-001 | J42: Access rights to administer scheduled jobs is restricted to authorised users.
B43: Application Name | C43: Application | D43: Data Center & Network Operation | E43: ITGC-DCNO-UPC-T03 | F43: Job Monitoring | G43: ITGC-DCNO-JM-R-002 | H43: Inappropriate changes are made to application systems or programs relevant to configuration changes in relation to the scheduled jobs. | I43: ITGC-DCNO-JM-C-002 | J43: Any changes to the application programs or source codes or configurations are adequately tested and approved by the appropriate management to ensure: 1. Requested changes are aligned to the business requirement 2. Changes to be migrated are in line with what is requested by the business / IT 3. Approval is provided for migration to production environment only after ensuring adequate testing of the changes and verifying business / IT approval for development of changes
B44: Application Name | C44: Application | D44: Data Center & Network Operation | E44: ITGC-DCNO-UPC-T03 | F44: Job Monitoring | G44: ITGC-DCNO-JM-R-003 | H44: Scheduled jobs are not adequately monitored for failures thereby impacting financial reporting associated with these jobs. | I44: ITGC-DCNO-JM-C-003 | J44: All the financial critical jobs are identified by the management having an impact on the financial reporting and approved for further monitoring.
B45: Application Name | C45: Application | D45: Data Center & Network Operation | E45: ITGC-DCNO-UPC-T03 | F45: Job Monitoring | G45: ITGC-DCNO-JM-R-003 | H45: Scheduled jobs are not adequately monitored for failures thereby impacting financial reporting associated with these jobs. | I45: ITGC-DCNO-JM-C-004 | J45: On a daily basis, control owner monitors all the critical financial related jobs to ensure that: 1. all the jobs are run successfully; 2. for the failures, investigation is carried out by the IT team and resolved as appropriate; 3. failed jobs are run successfully subsequently. | O45: ITGC-DCNO-JM-IUC-01 | P45: Failed Jobs report
...

Sheet DIM Assessment
C1: IT General Controls Testing - Design & Implementation Assessment
B3: ='Application Listing'!B3 -> Name of Client
B4: ='Application Listing'!B4 -> Audit Period
B5: A control will necessarily be considered as 'relevant for the audit' if the control addresses a significant risk/ fraud risk, or is an automated control, or is relating to a population where the size of such population in terms of numbers is significant.
B8: Process Code
B9: Process
B10: Risk ID
B11: Risk
B12: Assertions
B13: Risk/Assertion Classification
B14: Control ID
B15: Control description
B16: Is this control relevant control for purpose of audit (This question will not populate if IFCoFR reporting is applicable or control reliance is selected as 'Yes' for audit/specific account balance) (If response to this question is 'NO' then the responses for the below rows can be greyed out)
B19: Testing comprehensiveness of the control description | C19: Conclusion (Yes/ No/ Not Applicable) | D19: Remarks, if Not Applicable
B20: 1. Completeness - Does the control description evidence the operation of the control on every transaction, the control relates to.
B21: 2. Occurrence- Does the control description describe the evidence that the control was performed
B22: 3. Accuracy- Does the control description evidence that the control when performed fully addresses the risk to which the control relates to
B23: 4. Cut-off- Does the control description evidence the performance of the control before the transaction/ event occur or before it impacts the financial statements
B24: 5. Access and control- Is the control being performed by the appropriate person (i.e. competent and person who is not conflicted)
B27: To appropriately evaluate the design of relevant controls, the auditor considers the following elements: [Refer Para IG 11.4 of IFC GN]
B28: Nature and significance of the risks of material misstatement addressed by the control
B29: Characteristics or details of the control
B30: Factors to determine whether the control is appropriately designed, refer below: [Refer Para IG 11.5 to 11.11 of IFC GN]
B31: Appropriateness of the Control and its Correlation to the Risk/Assertion
B32: When determining appropriateness, a control that functions to prevent or detect misstatements should be more precise to mitigate the risk and address the related assertion. A control that is indirectly related to an assertion normally is less likely to prevent or detect misstatements in the assertion than a control that is directly related to an assertion. It is important that the assessment be applied for each risk/assertion that a control addresses.
B33: Appropriateness of the control considering the nature and significance of the risk
... B82: Risk Associated with Controls (Only if implementation is effective)

Sheet OE Testing
D1: IT General Controls Testing - Testing of Operating Effectiveness
B3: ='Application Listing'!B3 -> Name of Client | C3: ='Application Listing'!C3
B4: ='Application Listing'!B4 -> Audit Period | C4: ='Application Listing'!C4
B7: The controls to be populated will only be those controls where the Design and Implementation of the Control has been selected to be Effective.
B9: Process Code
B10: Process
B11: Risk ID
B12: Risk
B13: Assertions
B14: Risk/Assertion Classification
B15: Control ID
B16: Control description
B17: Conclusion of test of Design of Control
B18: Conclusion of test of Implementation of Control
B19: Test Operating Effectiveness (Inquiry supported by Observation/ Inspection/ Re-performance)
... B27: Conclusion on test of the accuracy and validity of the transaction

Sheet List Master
A1: Accuracy (T) | C1: Automated | E1: Annual | G1: System Generated | I1: Inquiry with Observation | K1: Low
A2: Accuracy and valuation (D) | C2: Semi-Automated | E2: Semi-annually | G2: Manual | I2: Inquiry with Inspection | K2: Medium
A3: All pervasive | C3: Manual/Review | E3: Quarterly | I3: Inquiry with Reperformance | K3: High
A4: Classification (T) | E4: Monthly | I4: Inquiry with Observation and Inspection
A5: Classification and understandability (D) | E5: Fortnightly | I5: Inquiry with Observation and Reperformance
A6: Completeness (AB) | E6: Weekly | I6: Inquiry with Inspection and Reperformance
A7: Completeness (D) | E7: Daily | I7: Inquiry with Observation, Inspection and Reperformance
A8: Completeness (T) | E8: Multiple times a day
A9: Cutoff (T) | E9: As needed
A10: Existence (AB)
A11: Not in compliance
A12: Occurrence (T)
A13: Occurrence and rights and obligations (D)
A14: Rights and obligations (AB)
A15: Valuation and allocation (AB)
